2020-08-28 19:10:56,257:app:ERROR:Exception on /search [GET]
Traceback (most recent call last):
  File "C:\Users\feruc\AppData\Roaming\Python\Python38\site-packages\flask\app.py", line 2447, in wsgi_app
    response = self.full_dispatch_request()
  File "C:\Users\feruc\AppData\Roaming\Python\Python38\site-packages\flask\app.py", line 1952, in full_dispatch_request
    rv = self.handle_user_exception(e)
  File "C:\Users\feruc\AppData\Roaming\Python\Python38\site-packages\flask_cors\extension.py", line 161, in wrapped_function
    return cors_after_request(app.make_response(f(*args, **kwargs)))
  File "C:\Users\feruc\AppData\Roaming\Python\Python38\site-packages\flask\app.py", line 1821, in handle_user_exception
    reraise(exc_type, exc_value, tb)
  File "C:\Users\feruc\AppData\Roaming\Python\Python38\site-packages\flask\_compat.py", line 39, in reraise
    raise value
  File "C:\Users\feruc\AppData\Roaming\Python\Python38\site-packages\flask\app.py", line 1950, in full_dispatch_request
    rv = self.dispatch_request()
  File "C:\Users\feruc\AppData\Roaming\Python\Python38\site-packages\flask\app.py", line 1936, in dispatch_request
    return self.view_functions[rule.endpoint](**req.view_args)
  File "c:\program files\python38\lib\site-packages\flask_apispec\annotations.py", line 118, in wrapped
    return wrapper(*args, **kwargs)
  File "c:\program files\python38\lib\site-packages\flask_apispec\wrapper.py", line 33, in __call__
    response = self.call_view(*args, **kwargs)
  File "c:\program files\python38\lib\site-packages\flask_apispec\wrapper.py", line 56, in call_view
    return self.func(*args, **kwargs)
  File "C:\localhost\GitHub\feruc\RaillWayTickets\server-side\app\routes\main\views.py", line 39, in get_schedules
    routes = get_fit_routes(routes_info)
  File "C:\localhost\GitHub\feruc\RaillWayTickets\server-side\app\routes\main\views.py", line 49, in get_fit_routes
    for i in range(len(routes_info)):
TypeError: object of type 'Query' has no len()
2020-08-28 19:12:43,854:app:ERROR:Exception on /search [GET]
Traceback (most recent call last):
  File "C:\Users\feruc\AppData\Roaming\Python\Python38\site-packages\flask\app.py", line 2447, in wsgi_app
    response = self.full_dispatch_request()
  File "C:\Users\feruc\AppData\Roaming\Python\Python38\site-packages\flask\app.py", line 1952, in full_dispatch_request
    rv = self.handle_user_exception(e)
  File "C:\Users\feruc\AppData\Roaming\Python\Python38\site-packages\flask_cors\extension.py", line 161, in wrapped_function
    return cors_after_request(app.make_response(f(*args, **kwargs)))
  File "C:\Users\feruc\AppData\Roaming\Python\Python38\site-packages\flask\app.py", line 1821, in handle_user_exception
    reraise(exc_type, exc_value, tb)
  File "C:\Users\feruc\AppData\Roaming\Python\Python38\site-packages\flask\_compat.py", line 39, in reraise
    raise value
  File "C:\Users\feruc\AppData\Roaming\Python\Python38\site-packages\flask\app.py", line 1950, in full_dispatch_request
    rv = self.dispatch_request()
  File "C:\Users\feruc\AppData\Roaming\Python\Python38\site-packages\flask\app.py", line 1936, in dispatch_request
    return self.view_functions[rule.endpoint](**req.view_args)
  File "c:\program files\python38\lib\site-packages\flask_apispec\annotations.py", line 118, in wrapped
    return wrapper(*args, **kwargs)
  File "c:\program files\python38\lib\site-packages\flask_apispec\wrapper.py", line 37, in __call__
    mv = self.marshal_result(rv, status_code)
  File "c:\program files\python38\lib\site-packages\flask_apispec\wrapper.py", line 66, in marshal_result
    dumped = schema.dump(result)
  File "c:\program files\python38\lib\site-packages\marshmallow\schema.py", line 557, in dump
    result = self._serialize(processed_obj, many=many)
  File "c:\program files\python38\lib\site-packages\marshmallow\schema.py", line 521, in _serialize
    value = field_obj.serialize(attr_name, obj, accessor=self.get_attribute)
  File "c:\program files\python38\lib\site-packages\marshmallow\fields.py", line 312, in serialize
    return self._serialize(value, attr, obj, **kwargs)
  File "c:\program files\python38\lib\site-packages\marshmallow\fields.py", line 700, in _serialize
    return [self.inner._serialize(each, attr, obj, **kwargs) for each in value]
  File "c:\program files\python38\lib\site-packages\marshmallow\fields.py", line 700, in <listcomp>
    return [self.inner._serialize(each, attr, obj, **kwargs) for each in value]
  File "c:\program files\python38\lib\site-packages\marshmallow\fields.py", line 567, in _serialize
    return schema.dump(nested_obj, many=many)
  File "c:\program files\python38\lib\site-packages\marshmallow\schema.py", line 557, in dump
    result = self._serialize(processed_obj, many=many)
  File "c:\program files\python38\lib\site-packages\marshmallow\schema.py", line 521, in _serialize
    value = field_obj.serialize(attr_name, obj, accessor=self.get_attribute)
  File "c:\program files\python38\lib\site-packages\marshmallow\fields.py", line 312, in serialize
    return self._serialize(value, attr, obj, **kwargs)
  File "c:\program files\python38\lib\site-packages\marshmallow\fields.py", line 1201, in _serialize
    return format_func(value)
  File "c:\program files\python38\lib\site-packages\marshmallow\utils.py", line 192, in isoformat
    return datetime.isoformat()
AttributeError: 'str' object has no attribute 'isoformat'
2020-09-05 21:30:04,433:app:WARNING:user:1 - failed to read profile: 'Query' object is not callable
2020-09-05 21:30:38,697:app:WARNING:user:1 - failed to read profile: 'Query' object is not callable
2020-09-05 21:31:27,206:app:WARNING:user:1 - failed to read profile: filter() got an unexpected keyword argument 'user_id'
2020-09-05 21:32:34,024:app:ERROR:Exception on /user_tickets [GET]
Traceback (most recent call last):
  File "C:\Users\feruc\AppData\Roaming\Python\Python38\site-packages\flask\app.py", line 2447, in wsgi_app
    response = self.full_dispatch_request()
  File "C:\Users\feruc\AppData\Roaming\Python\Python38\site-packages\flask\app.py", line 1952, in full_dispatch_request
    rv = self.handle_user_exception(e)
  File "C:\Users\feruc\AppData\Roaming\Python\Python38\site-packages\flask_cors\extension.py", line 161, in wrapped_function
    return cors_after_request(app.make_response(f(*args, **kwargs)))
  File "C:\Users\feruc\AppData\Roaming\Python\Python38\site-packages\flask\app.py", line 1821, in handle_user_exception
    reraise(exc_type, exc_value, tb)
  File "C:\Users\feruc\AppData\Roaming\Python\Python38\site-packages\flask\_compat.py", line 39, in reraise
    raise value
  File "C:\Users\feruc\AppData\Roaming\Python\Python38\site-packages\flask\app.py", line 1950, in full_dispatch_request
    rv = self.dispatch_request()
  File "C:\Users\feruc\AppData\Roaming\Python\Python38\site-packages\flask\app.py", line 1936, in dispatch_request
    return self.view_functions[rule.endpoint](**req.view_args)
  File "C:\Users\feruc\AppData\Roaming\Python\Python38\site-packages\flask\views.py", line 89, in view
    return self.dispatch_request(*args, **kwargs)
  File "C:\Users\feruc\AppData\Roaming\Python\Python38\site-packages\flask\views.py", line 163, in dispatch_request
    return meth(*args, **kwargs)
  File "c:\program files\python38\lib\site-packages\flask_jwt_extended\view_decorators.py", line 108, in wrapper
    return fn(*args, **kwargs)
  File "c:\program files\python38\lib\site-packages\flask_apispec\annotations.py", line 118, in wrapped
    return wrapper(*args, **kwargs)
  File "c:\program files\python38\lib\site-packages\flask_apispec\wrapper.py", line 33, in __call__
    response = self.call_view(*args, **kwargs)
  File "c:\program files\python38\lib\site-packages\flask_apispec\wrapper.py", line 56, in call_view
    return self.func(*args, **kwargs)
  File "C:\localhost\GitHub\feruc\RaillWayTickets\server-side\app\routes\profile\views.py", line 46, in get
    return UserInfoView.prepare_to_serialize(tickets)
AttributeError: type object 'UserInfoView' has no attribute 'prepare_to_serialize'
2020-09-05 21:38:09,616:app:ERROR:Exception on /user_tickets [GET]
Traceback (most recent call last):
  File "C:\Users\feruc\AppData\Roaming\Python\Python38\site-packages\flask\app.py", line 2447, in wsgi_app
    response = self.full_dispatch_request()
  File "C:\Users\feruc\AppData\Roaming\Python\Python38\site-packages\flask\app.py", line 1952, in full_dispatch_request
    rv = self.handle_user_exception(e)
  File "C:\Users\feruc\AppData\Roaming\Python\Python38\site-packages\flask_cors\extension.py", line 161, in wrapped_function
    return cors_after_request(app.make_response(f(*args, **kwargs)))
  File "C:\Users\feruc\AppData\Roaming\Python\Python38\site-packages\flask\app.py", line 1821, in handle_user_exception
    reraise(exc_type, exc_value, tb)
  File "C:\Users\feruc\AppData\Roaming\Python\Python38\site-packages\flask\_compat.py", line 39, in reraise
    raise value
  File "C:\Users\feruc\AppData\Roaming\Python\Python38\site-packages\flask\app.py", line 1950, in full_dispatch_request
    rv = self.dispatch_request()
  File "C:\Users\feruc\AppData\Roaming\Python\Python38\site-packages\flask\app.py", line 1936, in dispatch_request
    return self.view_functions[rule.endpoint](**req.view_args)
  File "C:\Users\feruc\AppData\Roaming\Python\Python38\site-packages\flask\views.py", line 89, in view
    return self.dispatch_request(*args, **kwargs)
  File "C:\Users\feruc\AppData\Roaming\Python\Python38\site-packages\flask\views.py", line 163, in dispatch_request
    return meth(*args, **kwargs)
  File "c:\program files\python38\lib\site-packages\flask_jwt_extended\view_decorators.py", line 108, in wrapper
    return fn(*args, **kwargs)
  File "c:\program files\python38\lib\site-packages\flask_apispec\annotations.py", line 118, in wrapped
    return wrapper(*args, **kwargs)
  File "c:\program files\python38\lib\site-packages\flask_apispec\wrapper.py", line 33, in __call__
    response = self.call_view(*args, **kwargs)
  File "c:\program files\python38\lib\site-packages\flask_apispec\wrapper.py", line 56, in call_view
    return self.func(*args, **kwargs)
  File "C:\localhost\GitHub\feruc\RaillWayTickets\server-side\app\routes\profile\views.py", line 46, in get
    return UsersTickets.prepare_to_serialize(tickets)
  File "C:\localhost\GitHub\feruc\RaillWayTickets\server-side\app\routes\profile\views.py", line 68, in prepare_to_serialize
    'arrival_time': arr_station_stop.arrival,
AttributeError: 'Stop' object has no attribute 'arrival'
2020-09-07 23:56:47,890:app:ERROR:Exception on /user_tickets [GET]
Traceback (most recent call last):
  File "C:\Users\feruc\AppData\Roaming\Python\Python38\site-packages\flask\app.py", line 2447, in wsgi_app
    response = self.full_dispatch_request()
  File "C:\Users\feruc\AppData\Roaming\Python\Python38\site-packages\flask\app.py", line 1952, in full_dispatch_request
    rv = self.handle_user_exception(e)
  File "C:\Users\feruc\AppData\Roaming\Python\Python38\site-packages\flask_cors\extension.py", line 161, in wrapped_function
    return cors_after_request(app.make_response(f(*args, **kwargs)))
  File "C:\Users\feruc\AppData\Roaming\Python\Python38\site-packages\flask\app.py", line 1821, in handle_user_exception
    reraise(exc_type, exc_value, tb)
  File "C:\Users\feruc\AppData\Roaming\Python\Python38\site-packages\flask\_compat.py", line 39, in reraise
    raise value
  File "C:\Users\feruc\AppData\Roaming\Python\Python38\site-packages\flask\app.py", line 1950, in full_dispatch_request
    rv = self.dispatch_request()
  File "C:\Users\feruc\AppData\Roaming\Python\Python38\site-packages\flask\app.py", line 1936, in dispatch_request
    return self.view_functions[rule.endpoint](**req.view_args)
  File "C:\Users\feruc\AppData\Roaming\Python\Python38\site-packages\flask\views.py", line 89, in view
    return self.dispatch_request(*args, **kwargs)
  File "C:\Users\feruc\AppData\Roaming\Python\Python38\site-packages\flask\views.py", line 163, in dispatch_request
    return meth(*args, **kwargs)
  File "c:\program files\python38\lib\site-packages\flask_jwt_extended\view_decorators.py", line 108, in wrapper
    return fn(*args, **kwargs)
  File "c:\program files\python38\lib\site-packages\flask_apispec\annotations.py", line 118, in wrapped
    return wrapper(*args, **kwargs)
  File "c:\program files\python38\lib\site-packages\flask_apispec\wrapper.py", line 33, in __call__
    response = self.call_view(*args, **kwargs)
  File "c:\program files\python38\lib\site-packages\flask_apispec\wrapper.py", line 56, in call_view
    return self.func(*args, **kwargs)
  File "C:\localhost\GitHub\feruc\RaillWayTickets\server-side\app\routes\profile\views.py", line 46, in get
    return UsersTickets.prepare_to_serialize(tickets)
  File "C:\localhost\GitHub\feruc\RaillWayTickets\server-side\app\routes\profile\views.py", line 61, in prepare_to_serialize
    dep_station = Station.query.get(dep_station_stop.station_id)
AttributeError: 'NoneType' object has no attribute 'station_id'
2020-09-07 23:59:25,179:app:ERROR:Exception on /user_tickets [GET]
Traceback (most recent call last):
  File "C:\Users\feruc\AppData\Roaming\Python\Python38\site-packages\flask\app.py", line 2447, in wsgi_app
    response = self.full_dispatch_request()
  File "C:\Users\feruc\AppData\Roaming\Python\Python38\site-packages\flask\app.py", line 1952, in full_dispatch_request
    rv = self.handle_user_exception(e)
  File "C:\Users\feruc\AppData\Roaming\Python\Python38\site-packages\flask_cors\extension.py", line 161, in wrapped_function
    return cors_after_request(app.make_response(f(*args, **kwargs)))
  File "C:\Users\feruc\AppData\Roaming\Python\Python38\site-packages\flask\app.py", line 1821, in handle_user_exception
    reraise(exc_type, exc_value, tb)
  File "C:\Users\feruc\AppData\Roaming\Python\Python38\site-packages\flask\_compat.py", line 39, in reraise
    raise value
  File "C:\Users\feruc\AppData\Roaming\Python\Python38\site-packages\flask\app.py", line 1950, in full_dispatch_request
    rv = self.dispatch_request()
  File "C:\Users\feruc\AppData\Roaming\Python\Python38\site-packages\flask\app.py", line 1936, in dispatch_request
    return self.view_functions[rule.endpoint](**req.view_args)
  File "C:\Users\feruc\AppData\Roaming\Python\Python38\site-packages\flask\views.py", line 89, in view
    return self.dispatch_request(*args, **kwargs)
  File "C:\Users\feruc\AppData\Roaming\Python\Python38\site-packages\flask\views.py", line 163, in dispatch_request
    return meth(*args, **kwargs)
  File "c:\program files\python38\lib\site-packages\flask_jwt_extended\view_decorators.py", line 108, in wrapper
    return fn(*args, **kwargs)
  File "c:\program files\python38\lib\site-packages\flask_apispec\annotations.py", line 118, in wrapped
    return wrapper(*args, **kwargs)
  File "c:\program files\python38\lib\site-packages\flask_apispec\wrapper.py", line 33, in __call__
    response = self.call_view(*args, **kwargs)
  File "c:\program files\python38\lib\site-packages\flask_apispec\wrapper.py", line 56, in call_view
    return self.func(*args, **kwargs)
  File "C:\localhost\GitHub\feruc\RaillWayTickets\server-side\app\routes\profile\views.py", line 46, in get
    return UsersTickets.prepare_to_serialize(tickets)
  File "C:\localhost\GitHub\feruc\RaillWayTickets\server-side\app\routes\profile\views.py", line 61, in prepare_to_serialize
    dep_station = Station.query.get(dep_station_stop.station_id)
AttributeError: 'NoneType' object has no attribute 'station_id'
2020-09-08 00:57:50,144:app:ERROR:Exception on /book_ticket [POST]
Traceback (most recent call last):
  File "C:\Users\feruc\AppData\Roaming\Python\Python38\site-packages\flask\app.py", line 2447, in wsgi_app
    response = self.full_dispatch_request()
  File "C:\Users\feruc\AppData\Roaming\Python\Python38\site-packages\flask\app.py", line 1952, in full_dispatch_request
    rv = self.handle_user_exception(e)
  File "C:\Users\feruc\AppData\Roaming\Python\Python38\site-packages\flask_cors\extension.py", line 161, in wrapped_function
    return cors_after_request(app.make_response(f(*args, **kwargs)))
  File "C:\Users\feruc\AppData\Roaming\Python\Python38\site-packages\flask\app.py", line 1821, in handle_user_exception
    reraise(exc_type, exc_value, tb)
  File "C:\Users\feruc\AppData\Roaming\Python\Python38\site-packages\flask\_compat.py", line 39, in reraise
    raise value
  File "C:\Users\feruc\AppData\Roaming\Python\Python38\site-packages\flask\app.py", line 1950, in full_dispatch_request
    rv = self.dispatch_request()
  File "C:\Users\feruc\AppData\Roaming\Python\Python38\site-packages\flask\app.py", line 1936, in dispatch_request
    return self.view_functions[rule.endpoint](**req.view_args)
  File "c:\program files\python38\lib\site-packages\flask_jwt_extended\view_decorators.py", line 108, in wrapper
    return fn(*args, **kwargs)
  File "c:\program files\python38\lib\site-packages\flask_apispec\annotations.py", line 118, in wrapped
    return wrapper(*args, **kwargs)
  File "c:\program files\python38\lib\site-packages\flask_apispec\wrapper.py", line 33, in __call__
    response = self.call_view(*args, **kwargs)
  File "c:\program files\python38\lib\site-packages\flask_apispec\wrapper.py", line 56, in call_view
    return self.func(*args, **kwargs)
  File "C:\localhost\GitHub\feruc\RaillWayTickets\server-side\app\routes\main\views.py", line 76, in book_ticket
    train_dep_time = session.query(Schedule.departure_time).get(kwargs.get('schedule_id'))
  File "c:\program files\python38\lib\site-packages\sqlalchemy\orm\query.py", line 1021, in get
    return self._get_impl(ident, loading.load_on_pk_identity)
  File "c:\program files\python38\lib\site-packages\sqlalchemy\orm\query.py", line 1082, in _get_impl
    mapper = self._only_full_mapper_zero("get")
  File "c:\program files\python38\lib\site-packages\sqlalchemy\orm\query.py", line 437, in _only_full_mapper_zero
    raise sa_exc.InvalidRequestError(
sqlalchemy.exc.InvalidRequestError: get() can only be used against a single mapped class.
2020-09-08 01:01:20,213:app:ERROR:Exception on /book_ticket [POST]
Traceback (most recent call last):
  File "c:\program files\python38\lib\site-packages\sqlalchemy\engine\base.py", line 1277, in _execute_context
    self.dialect.do_execute(
  File "c:\program files\python38\lib\site-packages\sqlalchemy\engine\default.py", line 593, in do_execute
    cursor.execute(statement, parameters)
sqlite3.IntegrityError: NOT NULL constraint failed: tickets.place_num

The above exception was the direct cause of the following exception:

Traceback (most recent call last):
  File "C:\Users\feruc\AppData\Roaming\Python\Python38\site-packages\flask\app.py", line 2447, in wsgi_app
    response = self.full_dispatch_request()
  File "C:\Users\feruc\AppData\Roaming\Python\Python38\site-packages\flask\app.py", line 1952, in full_dispatch_request
    rv = self.handle_user_exception(e)
  File "C:\Users\feruc\AppData\Roaming\Python\Python38\site-packages\flask_cors\extension.py", line 161, in wrapped_function
    return cors_after_request(app.make_response(f(*args, **kwargs)))
  File "C:\Users\feruc\AppData\Roaming\Python\Python38\site-packages\flask\app.py", line 1821, in handle_user_exception
    reraise(exc_type, exc_value, tb)
  File "C:\Users\feruc\AppData\Roaming\Python\Python38\site-packages\flask\_compat.py", line 39, in reraise
    raise value
  File "C:\Users\feruc\AppData\Roaming\Python\Python38\site-packages\flask\app.py", line 1950, in full_dispatch_request
    rv = self.dispatch_request()
  File "C:\Users\feruc\AppData\Roaming\Python\Python38\site-packages\flask\app.py", line 1936, in dispatch_request
    return self.view_functions[rule.endpoint](**req.view_args)
  File "c:\program files\python38\lib\site-packages\flask_jwt_extended\view_decorators.py", line 108, in wrapper
    return fn(*args, **kwargs)
  File "c:\program files\python38\lib\site-packages\flask_apispec\annotations.py", line 118, in wrapped
    return wrapper(*args, **kwargs)
  File "c:\program files\python38\lib\site-packages\flask_apispec\wrapper.py", line 33, in __call__
    response = self.call_view(*args, **kwargs)
  File "c:\program files\python38\lib\site-packages\flask_apispec\wrapper.py", line 56, in call_view
    return self.func(*args, **kwargs)
  File "C:\localhost\GitHub\feruc\RaillWayTickets\server-side\app\routes\main\views.py", line 87, in book_ticket
    session.commit()
  File "c:\program files\python38\lib\site-packages\sqlalchemy\orm\scoping.py", line 163, in do
    return getattr(self.registry(), name)(*args, **kwargs)
  File "c:\program files\python38\lib\site-packages\sqlalchemy\orm\session.py", line 1042, in commit
    self.transaction.commit()
  File "c:\program files\python38\lib\site-packages\sqlalchemy\orm\session.py", line 504, in commit
    self._prepare_impl()
  File "c:\program files\python38\lib\site-packages\sqlalchemy\orm\session.py", line 483, in _prepare_impl
    self.session.flush()
  File "c:\program files\python38\lib\site-packages\sqlalchemy\orm\session.py", line 2523, in flush
    self._flush(objects)
  File "c:\program files\python38\lib\site-packages\sqlalchemy\orm\session.py", line 2664, in _flush
    transaction.rollback(_capture_exception=True)
  File "c:\program files\python38\lib\site-packages\sqlalchemy\util\langhelpers.py", line 68, in __exit__
    compat.raise_(
  File "c:\program files\python38\lib\site-packages\sqlalchemy\util\compat.py", line 178, in raise_
    raise exception
  File "c:\program files\python38\lib\site-packages\sqlalchemy\orm\session.py", line 2624, in _flush
    flush_context.execute()
  File "c:\program files\python38\lib\site-packages\sqlalchemy\orm\unitofwork.py", line 422, in execute
    rec.execute(self)
  File "c:\program files\python38\lib\site-packages\sqlalchemy\orm\unitofwork.py", line 586, in execute
    persistence.save_obj(
  File "c:\program files\python38\lib\site-packages\sqlalchemy\orm\persistence.py", line 239, in save_obj
    _emit_insert_statements(
  File "c:\program files\python38\lib\site-packages\sqlalchemy\orm\persistence.py", line 1135, in _emit_insert_statements
    result = cached_connections[connection].execute(
  File "c:\program files\python38\lib\site-packages\sqlalchemy\engine\base.py", line 1014, in execute
    return meth(self, multiparams, params)
  File "c:\program files\python38\lib\site-packages\sqlalchemy\sql\elements.py", line 298, in _execute_on_connection
    return connection._execute_clauseelement(self, multiparams, params)
  File "c:\program files\python38\lib\site-packages\sqlalchemy\engine\base.py", line 1127, in _execute_clauseelement
    ret = self._execute_context(
  File "c:\program files\python38\lib\site-packages\sqlalchemy\engine\base.py", line 1317, in _execute_context
    self._handle_dbapi_exception(
  File "c:\program files\python38\lib\site-packages\sqlalchemy\engine\base.py", line 1511, in _handle_dbapi_exception
    util.raise_(
  File "c:\program files\python38\lib\site-packages\sqlalchemy\util\compat.py", line 178, in raise_
    raise exception
  File "c:\program files\python38\lib\site-packages\sqlalchemy\engine\base.py", line 1277, in _execute_context
    self.dialect.do_execute(
  File "c:\program files\python38\lib\site-packages\sqlalchemy\engine\default.py", line 593, in do_execute
    cursor.execute(statement, parameters)
sqlalchemy.exc.IntegrityError: (sqlite3.IntegrityError) NOT NULL constraint failed: tickets.place_num
[SQL: INSERT INTO tickets (user_id, departure_stop, arrival_stop, cost, wagon_id, place_num, schedule_id, is_booked, book_end_date) VALUES (?, ?, ?, ?, ?, ?, ?, ?, ?)]
[parameters: (1, 1, 4, 34, 1, None, 1, 1, '2020-09-27 00:00:00.000000')]
(Background on this error at: http://sqlalche.me/e/13/gkpj)
2020-09-09 23:55:26,428:app:ERROR:Exception on /delete_ticket [POST]
Traceback (most recent call last):
  File "C:\Users\feruc\AppData\Roaming\Python\Python38\site-packages\flask\app.py", line 2447, in wsgi_app
    response = self.full_dispatch_request()
  File "C:\Users\feruc\AppData\Roaming\Python\Python38\site-packages\flask\app.py", line 1952, in full_dispatch_request
    rv = self.handle_user_exception(e)
  File "C:\Users\feruc\AppData\Roaming\Python\Python38\site-packages\flask_cors\extension.py", line 161, in wrapped_function
    return cors_after_request(app.make_response(f(*args, **kwargs)))
  File "C:\Users\feruc\AppData\Roaming\Python\Python38\site-packages\flask\app.py", line 1821, in handle_user_exception
    reraise(exc_type, exc_value, tb)
  File "C:\Users\feruc\AppData\Roaming\Python\Python38\site-packages\flask\_compat.py", line 39, in reraise
    raise value
  File "C:\Users\feruc\AppData\Roaming\Python\Python38\site-packages\flask\app.py", line 1950, in full_dispatch_request
    rv = self.dispatch_request()
  File "C:\Users\feruc\AppData\Roaming\Python\Python38\site-packages\flask\app.py", line 1936, in dispatch_request
    return self.view_functions[rule.endpoint](**req.view_args)
  File "c:\program files\python38\lib\site-packages\flask_jwt_extended\view_decorators.py", line 108, in wrapper
    return fn(*args, **kwargs)
  File "C:\localhost\GitHub\feruc\RaillWayTickets\server-side\app\decorators.py", line 13, in decorated_f
    return make_response(401)
  File "C:\Users\feruc\AppData\Roaming\Python\Python38\site-packages\flask\helpers.py", line 223, in make_response
    return current_app.make_response(args)
  File "C:\Users\feruc\AppData\Roaming\Python\Python38\site-packages\flask\app.py", line 2127, in make_response
    raise TypeError(
TypeError: The view function did not return a valid response. The return type must be a string, dict, tuple, Response instance, or WSGI callable, but it was a int.
2020-09-10 00:01:52,638:app:INFO:manager 2 deleted ticket
2020-09-10 00:02:48,046:app:INFO:manager 2 deleted ticket
2020-09-10 00:23:17,810:app:INFO:manager 2 deleted ticket
2020-09-10 00:23:22,909:app:ERROR:Exception on /search_tickets [POST]
Traceback (most recent call last):
  File "C:\Users\feruc\AppData\Roaming\Python\Python38\site-packages\flask\app.py", line 2447, in wsgi_app
    response = self.full_dispatch_request()
  File "C:\Users\feruc\AppData\Roaming\Python\Python38\site-packages\flask\app.py", line 1952, in full_dispatch_request
    rv = self.handle_user_exception(e)
  File "C:\Users\feruc\AppData\Roaming\Python\Python38\site-packages\flask_cors\extension.py", line 161, in wrapped_function
    return cors_after_request(app.make_response(f(*args, **kwargs)))
  File "C:\Users\feruc\AppData\Roaming\Python\Python38\site-packages\flask\app.py", line 1821, in handle_user_exception
    reraise(exc_type, exc_value, tb)
  File "C:\Users\feruc\AppData\Roaming\Python\Python38\site-packages\flask\_compat.py", line 39, in reraise
    raise value
  File "C:\Users\feruc\AppData\Roaming\Python\Python38\site-packages\flask\app.py", line 1950, in full_dispatch_request
    rv = self.dispatch_request()
  File "C:\Users\feruc\AppData\Roaming\Python\Python38\site-packages\flask\app.py", line 1936, in dispatch_request
    return self.view_functions[rule.endpoint](**req.view_args)
  File "c:\program files\python38\lib\site-packages\flask_jwt_extended\view_decorators.py", line 108, in wrapper
    return fn(*args, **kwargs)
  File "C:\localhost\GitHub\feruc\RaillWayTickets\server-side\app\decorators.py", line 14, in decorated_f
    return f(*args, **kwargs)
  File "c:\program files\python38\lib\site-packages\flask_apispec\annotations.py", line 118, in wrapped
    return wrapper(*args, **kwargs)
  File "c:\program files\python38\lib\site-packages\flask_apispec\wrapper.py", line 33, in __call__
    response = self.call_view(*args, **kwargs)
  File "c:\program files\python38\lib\site-packages\flask_apispec\wrapper.py", line 56, in call_view
    return self.func(*args, **kwargs)
  File "C:\localhost\GitHub\feruc\RaillWayTickets\server-side\app\routes\profile\views.py", line 85, in search_tickets
    return make_response(400)
  File "C:\Users\feruc\AppData\Roaming\Python\Python38\site-packages\flask\helpers.py", line 223, in make_response
    return current_app.make_response(args)
  File "C:\Users\feruc\AppData\Roaming\Python\Python38\site-packages\flask\app.py", line 2127, in make_response
    raise TypeError(
TypeError: The view function did not return a valid response. The return type must be a string, dict, tuple, Response instance, or WSGI callable, but it was a int.
2020-09-10 00:26:03,520:app:INFO:manager 2 deleted ticket
2020-09-10 00:26:08,790:app:INFO:manager 2  accessed tickets list
2020-09-10 00:26:08,830:app:ERROR:Exception on /search_tickets [POST]
Traceback (most recent call last):
  File "C:\Users\feruc\AppData\Roaming\Python\Python38\site-packages\flask\app.py", line 2447, in wsgi_app
    response = self.full_dispatch_request()
  File "C:\Users\feruc\AppData\Roaming\Python\Python38\site-packages\flask\app.py", line 1952, in full_dispatch_request
    rv = self.handle_user_exception(e)
  File "C:\Users\feruc\AppData\Roaming\Python\Python38\site-packages\flask_cors\extension.py", line 161, in wrapped_function
    return cors_after_request(app.make_response(f(*args, **kwargs)))
  File "C:\Users\feruc\AppData\Roaming\Python\Python38\site-packages\flask\app.py", line 1821, in handle_user_exception
    reraise(exc_type, exc_value, tb)
  File "C:\Users\feruc\AppData\Roaming\Python\Python38\site-packages\flask\_compat.py", line 39, in reraise
    raise value
  File "C:\Users\feruc\AppData\Roaming\Python\Python38\site-packages\flask\app.py", line 1950, in full_dispatch_request
    rv = self.dispatch_request()
  File "C:\Users\feruc\AppData\Roaming\Python\Python38\site-packages\flask\app.py", line 1936, in dispatch_request
    return self.view_functions[rule.endpoint](**req.view_args)
  File "c:\program files\python38\lib\site-packages\flask_jwt_extended\view_decorators.py", line 108, in wrapper
    return fn(*args, **kwargs)
  File "C:\localhost\GitHub\feruc\RaillWayTickets\server-side\app\decorators.py", line 14, in decorated_f
    return f(*args, **kwargs)
  File "c:\program files\python38\lib\site-packages\flask_apispec\annotations.py", line 118, in wrapped
    return wrapper(*args, **kwargs)
  File "c:\program files\python38\lib\site-packages\flask_apispec\wrapper.py", line 33, in __call__
    response = self.call_view(*args, **kwargs)
  File "c:\program files\python38\lib\site-packages\flask_apispec\wrapper.py", line 56, in call_view
    return self.func(*args, **kwargs)
  File "C:\localhost\GitHub\feruc\RaillWayTickets\server-side\app\routes\profile\views.py", line 83, in search_tickets
    tickets = get_tickets(**kwargs)
  File "C:\localhost\GitHub\feruc\RaillWayTickets\server-side\app\routes\profile\views.py", line 141, in get_tickets
    return session.query(Ticket).get(kwargs.get('ticket_id')).all()
AttributeError: 'Ticket' object has no attribute 'all'
2020-09-10 00:26:58,490:app:INFO:manager 2 deleted ticket
2020-09-10 00:27:03,405:app:INFO:manager 2  accessed tickets list
2020-09-10 00:27:03,440:app:INFO:manager 2  accessed tickets list
2020-09-10 00:27:03,440:app:ERROR:Exception on /search_tickets [POST]
Traceback (most recent call last):
  File "C:\Users\feruc\AppData\Roaming\Python\Python38\site-packages\flask\app.py", line 2447, in wsgi_app
    response = self.full_dispatch_request()
  File "C:\Users\feruc\AppData\Roaming\Python\Python38\site-packages\flask\app.py", line 1952, in full_dispatch_request
    rv = self.handle_user_exception(e)
  File "C:\Users\feruc\AppData\Roaming\Python\Python38\site-packages\flask_cors\extension.py", line 161, in wrapped_function
    return cors_after_request(app.make_response(f(*args, **kwargs)))
  File "C:\Users\feruc\AppData\Roaming\Python\Python38\site-packages\flask\app.py", line 1821, in handle_user_exception
    reraise(exc_type, exc_value, tb)
  File "C:\Users\feruc\AppData\Roaming\Python\Python38\site-packages\flask\_compat.py", line 39, in reraise
    raise value
  File "C:\Users\feruc\AppData\Roaming\Python\Python38\site-packages\flask\app.py", line 1950, in full_dispatch_request
    rv = self.dispatch_request()
  File "C:\Users\feruc\AppData\Roaming\Python\Python38\site-packages\flask\app.py", line 1936, in dispatch_request
    return self.view_functions[rule.endpoint](**req.view_args)
  File "c:\program files\python38\lib\site-packages\flask_jwt_extended\view_decorators.py", line 108, in wrapper
    return fn(*args, **kwargs)
  File "C:\localhost\GitHub\feruc\RaillWayTickets\server-side\app\decorators.py", line 14, in decorated_f
    return f(*args, **kwargs)
  File "c:\program files\python38\lib\site-packages\flask_apispec\annotations.py", line 118, in wrapped
    return wrapper(*args, **kwargs)
  File "c:\program files\python38\lib\site-packages\flask_apispec\wrapper.py", line 33, in __call__
    response = self.call_view(*args, **kwargs)
  File "c:\program files\python38\lib\site-packages\flask_apispec\wrapper.py", line 56, in call_view
    return self.func(*args, **kwargs)
  File "C:\localhost\GitHub\feruc\RaillWayTickets\server-side\app\routes\profile\views.py", line 85, in search_tickets
    return UsersTickets.prepare_to_serialize(tickets)
  File "C:\localhost\GitHub\feruc\RaillWayTickets\server-side\app\routes\profile\views.py", line 52, in prepare_to_serialize
    for ticket in tickets:
TypeError: 'Ticket' object is not iterable
2020-09-10 00:27:28,930:app:INFO:manager 2 deleted ticket
2020-09-10 00:27:34,525:app:INFO:manager 2  accessed tickets list
2020-09-10 00:27:34,565:app:INFO:manager 2  accessed tickets list
2020-09-10 00:29:55,970:app:INFO:manager 2 deleted ticket
2020-09-10 00:30:03,570:app:INFO:manager 2  accessed tickets list
2020-09-10 00:30:03,665:app:INFO:manager 2  accessed tickets list
2020-09-10 00:31:10,192:app:INFO:manager 2 deleted ticket
2020-09-10 00:31:15,798:app:INFO:manager 2  accessed tickets list
2020-09-10 00:31:15,833:app:INFO:manager 2  accessed tickets list
2020-09-10 22:50:52,417:app:INFO:manager 2 deleted ticket
2020-09-10 22:50:57,986:app:INFO:manager 2  accessed tickets list
2020-09-10 22:50:58,026:app:INFO:manager 2  accessed tickets list
2020-09-10 22:52:47,212:app:INFO:manager 2 deleted ticket
2020-09-10 22:52:54,346:app:INFO:manager 2  accessed tickets list
2020-09-10 22:52:54,376:app:INFO:manager 2  accessed tickets list
2020-09-10 22:54:18,926:app:INFO:manager 2 deleted ticket
2020-09-10 22:54:23,576:app:INFO:manager 2  accessed tickets list
2020-09-10 22:54:23,601:app:INFO:manager 2  accessed tickets list
2020-09-10 23:12:15,658:app:INFO:manager 2  accessed tickets list
2020-09-10 23:12:21,728:app:INFO:manager 2 deleted ticket
2020-09-10 23:12:27,363:app:INFO:manager 2  accessed tickets list
2020-09-10 23:12:27,398:app:INFO:manager 2  accessed tickets list
